Workbook

Sheet Juri 1
J7: RUBRIK PENILAIAN WAWANCARA DUTA PNJ BATCH 5
D8: NAMA JURI: Juri 1
C9: No | D9: NAMA PESERTA | E9: JENIS KELAMIN | F9: JURUSAN | G9: ANGKATAN | H9: Ekspresi, Etika, Kepercayaan Diri | I9: Berpikir Kritis, Kreatif, Inisiatif, | J9: Komitmen Terhadap Duta dan Institusi | K9: Kemampuan Komunikasi, Argumentasi | L9: Personaliti Kepemimpinan & Keteraturan | M9: Manajemen Emosi | N9: Sikap Kooperatif | O9: Penilaian Diri dan Tujuan Pribadi | P9: Rekomendasi Lolos Seleksi Wawancara (%) | Q9: Saran dan Perbaikan
C10: 1 | D10: Aditya Pratama | E10: Laki-laki | F10: Administrasi Niaga | G10: 2024 | H10: 85 | I10: 90 | J10: 85 | K10: 80 | L10: 80 | M10: 74 | N10: 80 | O10: 90 | P10: 83
C11: 2 | D11: Budi Santoso | E11: Laki-laki | F11: Teknik Grafika dan Penerbitan | G11: 2024 | H11: 80 | I11: 87 | J11: 82 | K11: 85 | L11: 80 | M11: 82 | N11: 80 | O11: 80 | P11: 82
C12: 3 | D12: Citra Lestari | E12: Perempuan | F12: Teknik Sipil | G12: 2023 | H12: 85 | I12: 85 | J12: 90 | K12: 85 | L12: 85 | M12: 80 | N12: 85 | O12: 80 | P12: 84.375
C13: 4 | D13: Dwi Anggraini | E13: Perempuan | F13: Akutansi | G13: 2024 | H13: 80 | I13: 83 | J13: 85 | K13: 90 | L13: 75 | M13: 77 | N13: 86 | O13: 80 | P13: 82
C14: 5 | D14: Eka Saputra | E14: Laki-laki | F14: Teknik Sipil | G14: 2024 | H14: 78 | I14: 87 | J14: 90 | K14: 80 | L14: 78 | M14: 70 | N14: 80 | O14: 80 | P14: 80.375
C15: 6 | D15: Fajar Ramadhan | E15: Laki-laki | F15: Teknik Mesin | G15: 2023 | H15: 85 | I15: 85 | J15: 90 | K15: 85 | L15: 85 | M15: 80 | N15: 85 | O15: 80 | P15: 84.375
C16: 7 | D16: Gita Permata | E16: Perempuan | F16: Teknik Informatika dan Komputer | G16: 2024 | H16: 83 | I16: 85 | J16: 85 | K16: 85 | L16: 75 | M16: 77 | N16: 80 | O16: 80 | P16: 81.25
C17: 8 | D17: Hendra Wijaya | E17: Laki-laki | F17: Teknik Sipil | G17: 2024 | H17: 77 | I17: 85 | J17: 82 | K17: 80 | L17: 80 | M17: 70 | N17: 87 | O17: 85 | P17: 80.75
C18: 9 | D18: Indah Puspitasari | E18: Perempuan | F18: Teknik Mesin | G18: 2024 | H18: 95 | I18: 82 | J18: 87 | K18: 75 | L18: 70 | M18: 75 | N18: 87 | O18: 85 | P18: 82
C19: 10 | D19: Joko Hartono | E19: Laki-laki | F19: Administrasi Niaga | G19: 2024 | H19: 80 | I19: 82 | J19: 85 | K19: 87 | L19: 80 | M19: 76 | N19: 80 | O19: 80 | P19: 81.25
C20: 11 | D20: Kartika Sari | E20: Perempuan | F20: Akutansi | G20: 2023 | H20: 75 | I20: 85 | J20: 87 | K20: 83 | L20: 85 | M20: 70 | N20: 85 | O20: 80 | P20: 81.25
C21: 12 | D21: Laila Fitriani | E21: Perempuan | F21: Administrasi Niaga | G21: 2024 | H21: 80 | I21: 81 | J21: 85 | K21: 80 | L21: 80 | M21: 76 | N21: 90 | O21: 83 | P21: 81.875
... C58: 49 | D58: Teguh Prabowo | E58: Laki-laki | F58: Administrasi Niaga | G58: 2023 | H58: 84 | I58: 83 | J58: 82 | K58: 80 | L58: 85 | M58: 78 | N58: 75 | O58: 90 | P58: 82.125
C59: 50 | D59: Anisa Rahmawati | P59: #DIV/0!
C63: BOBOT | H63: 0.25 | I63: 0.2 | J63: 0.3 | K63: 0.25

Sheet Juri 2
J7: RUBRIK PENILAIAN WAWANCARA DUTA PNJ BATCH 5
D8: NAMA JURI: Juri 2
C9: No | D9: NAMA PESERTA | E9: JENIS KELAMIN | F9: JURUSAN | G9: ANGKATAN | H9: Ekspresi, Etika, Kepercayaan Diri | I9: Berpikir Kritis, Kreatif, Inisiatif, | J9: Komitmen Terhadap Duta dan Institusi | K9: Kemampuan Komunikasi, Argumentasi | L9: Opening & Public Speaking | M9: Wawasan & Keilmuan | N9: Kemampuan Berbahasa inggris | O9: Personaliti Kepemimpinan | P9: Rekomendasi Lolos Seleksi Wawancara (%) | Q9: Saran dan Perbaikan
C10: 1 | D10: Aditya Pratama | E10: Laki-laki | F10: Administrasi Niaga | G10: 2024 | H10: 85 | I10: 85 | J10: 85 | K10: 85 | L10: 85 | M10: 85 | N10: 70 | O10: 85 | P10: =(H10+I10+J10+K10+L10+M10+N10+O10)/8 -> 83.125
C11: 2 | D11: Budi Santoso | E11: Laki-laki | F11: Teknik Grafika dan Penerbitan | G11: 2024 | H11: 83 | I11: 83 | J11: 85 | K11: 85 | L11: 85 | M11: 85 | N11: 70 | O11: 85 | P11: =(H11+I11+J11+K11+L11+M11+N11+O11)/8 -> 82.625
C12: 3 | D12: Citra Lestari | E12: Perempuan | F12: Teknik Sipil | G12: 2023 | H12: 90 | I12: 88 | J12: 85 | K12: 90 | L12: 90 | M12: 90 | N12: 90 | O12: 90 | P12: =(H12+I12+J12+K12+L12+M12+N12+O12)/8 -> 89.125
C13: 4 | D13: Dwi Anggraini | E13: Perempuan | F13: Akutansi | G13: 2024 | H13: 88 | I13: 88 | J13: 85 | K13: 85 | L13: 85 | M13: 88 | N13: 70 | O13: 85 | P13: =(H13+I13+J13+K13+L13+M13+N13+O13)/8 -> 84.25
C14: 5 | D14: Eka Saputra | E14: Laki-laki | F14: Teknik Sipil | G14: 2024 | H14: 88 | I14: 88 | J14: 85 | K14: 88 | L14: 88 | M14: 88 | N14: 70 | O14: 88 | P14: =(H14+I14+J14+K14+L14+M14+N14+O14)/8 -> 85.375
C15: 6 | D15: Fajar Ramadhan | E15: Laki-laki | F15: Teknik Mesin | G15: 2023 | H15: 87 | I15: 87 | J15: 87 | K15: 87 | L15: 87 | M15: 87 | N15: 70 | O15: 87 | P15: =(H15+I15+J15+K15+L15+M15+N15+O15)/8 -> 84.875
C16: 7 | D16: Gita Permata | E16: Perempuan | F16: Teknik Informatika dan Komputer | G16: 2024 | H16: 90 | I16: 85 | J16: 85 | K16: 90 | L16: 88 | M16: 88 | N16: 80 | O16: 88 | P16: =(H16+I16+J16+K16+L16+M16+N16+O16)/8 -> 86.75
C17: 8 | D17: Hendra Wijaya | E17: Laki-laki | F17: Teknik Sipil | G17: 2024 | H17: 85 | I17: 85 | J17: 85 | K17: 85 | L17: 85 | M17: 85 | N17: 70 | O17: 85 | P17: =(H17+I17+J17+K17+L17+M17+N17+O17)/8 -> 83.125
C18: 9 | D18: Indah Puspitasari | E18: Perempuan | F18: Teknik Mesin | G18: 2024 | H18: 88 | I18: 85 | J18: 85 | K18: 88 | L18: 85 | M18: 88 | N18: 70 | O18: 85 | P18: =(H18+I18+J18+K18+L18+M18+N18+O18)/8 -> 84.25
C19: 10 | D19: Joko Hartono | E19: Laki-laki | F19: Administrasi Niaga | G19: 2024 | H19: 90 | I19: 85 | J19: 85 | K19: 90 | L19: 88 | M19: 85 | N19: 70 | O19: 85 | P19: =(H19+I19+J19+K19+L19+M19+N19+O19)/8 -> 84.75
C20: 11 | D20: Kartika Sari | E20: Perempuan | F20: Akutansi | G20: 2023 | H20: 90 | I20: 88 | J20: 85 | K20: 90 | L20: 85 | M20: 85 | N20: 70 | O20: 88 | P20: =(H20+I20+J20+K20+L20+M20+N20+O20)/8 -> 85.125
C21: 12 | D21: Laila Fitriani | E21: Perempuan | F21: Administrasi Niaga | G21: 2024 | H21: 90 | I21: 85 | J21: 85 | K21: 90 | L21: 85 | M21: 85 | N21: 90 | O21: 88 | P21: =(H21+I21+J21+K21+L21+M21+N21+O21)/8 -> 87.25
... C58: 49 | D58: Teguh Prabowo | E58: Laki-laki | F58: Administrasi Niaga | G58: 2023 | H58: 86 | I58: 86 | J58: 86 | K58: 86 | L58: 80 | M58: 86 | N58: 70 | O58: 86 | P58: =(H58+I58+J58+K58+L58+M58+N58+O58)/8 -> 83.25
C59: 50 | D59: Anisa Rahmawati | P59: #DIV/0!
C63: BOBOT | H63: 0.25 | I63: 0.2 | J63: 0.3 | K63: 0.25

Sheet Juri 3
J7: RUBRIK PENILAIAN WAWANCARA DUTA PNJ BATCH 5
D8: NAMA JURI: Juri 3
C9: No | D9: NAMA PESERTA | E9: JENIS KELAMIN | F9: JURUSAN | G9: ANGKATAN | H9: Ekspresi, Etika, Kepercayaan Diri | I9: Berpikir Kritis, Kreatif, Inisiatif, | J9: Komitmen Terhadap Duta dan Institusi | K9: Kemampuan Komunikasi, Argumentasi | L9: Opening & Public Speaking | M9: Body Language | N9: Kreativitas dan Invoasi | O9: Grooming & Look | P9: Rekomendasi Lolos Seleksi Wawancara (%) | Q9: Saran dan Perbaikan | S9: =ROUND(T7,0) -> 0
C10: 1 | D10: Aditya Pratama | E10: Laki-laki | F10: Administrasi Niaga | G10: 2024 | H10: 85 | I10: 90 | J10: 85 | K10: 88 | L10: 88 | M10: 88 | N10: 88 | O10: 90 | P10: =(H10+I10+J10+K10+L10+M10+N10+O10)/8 -> 87.75 | R10: =round(AVERAGE(L10,'Juri 2'!L10),2) -> 86.5 | S10: =round(AVERAGE(H10,'Juri 2'!H10,'Juri 1'!H10),2) -> 85 | T10: =round(AVERAGE(I10,'Juri 2'!I10,'Juri 1'!I10),2) -> 88.33 | U10: =round(AVERAGE(J10,'Juri 2'!J10,'Juri 1'!J10),2) -> 85 | V10: =round(AVERAGE(K10,'Juri 2'!K10,'Juri 1'!K10),2) -> 84.33
C11: 2 | D11: Budi Santoso | E11: Laki-laki | F11: Teknik Grafika dan Penerbitan | G11: 2024 | H11: 70 | I11: 70 | J11: 70 | K11: 77 | L11: 70 | M11: 80 | N11: 80 | O11: 80 | P11: =(H11+I11+J11+K11+L11+M11+N11+O11)/8 -> 74.625 | R11: =round(AVERAGE(L11,'Juri 2'!L11),2) -> 77.5 | S11: =round(AVERAGE(H11,'Juri 2'!H11,'Juri 1'!H11),2) -> 77.67 | T11: =round(AVERAGE(I11,'Juri 2'!I11,'Juri 1'!I11),2) -> 80 | U11: =round(AVERAGE(J11,'Juri 2'!J11,'Juri 1'!J11),2) -> 79 | V11: =round(AVERAGE(K11,'Juri 2'!K11,'Juri 1'!K11),2) -> 82.33
C12: 3 | D12: Citra Lestari | E12: Perempuan | F12: Teknik Sipil | G12: 2023 | H12: 90 | I12: 85 | J12: 88 | K12: 88 | L12: 90 | M12: 90 | N12: 85 | O12: 89 | P12: =(H12+I12+J12+K12+L12+M12+N12+O12)/8 -> 88.125 | R12: =round(AVERAGE(L12,'Juri 2'!L12),2) -> 90 | S12: =round(AVERAGE(H12,'Juri 2'!H12,'Juri 1'!H12),2) -> 88.33 | T12: =round(AVERAGE(I12,'Juri 2'!I12,'Juri 1'!I12),2) -> 86 | U12: =round(AVERAGE(J12,'Juri 2'!J12,'Juri 1'!J12),2) -> 87.67 | V12: =round(AVERAGE(K12,'Juri 2'!K12,'Juri 1'!K12),2) -> 87.67
C13: 4 | D13: Dwi Anggraini | E13: Perempuan | F13: Akutansi | G13: 2024 | H13: 90 | I13: 90 | J13: 85 | K13: 89 | L13: 88 | M13: 88 | N13: 85 | O13: 85 | P13: =(H13+I13+J13+K13+L13+M13+N13+O13)/8 -> 87.5 | R13: =round(AVERAGE(L13,'Juri 2'!L13),2) -> 86.5 | S13: =round(AVERAGE(H13,'Juri 2'!H13,'Juri 1'!H13),2) -> 86 | T13: =round(AVERAGE(I13,'Juri 2'!I13,'Juri 1'!I13),2) -> 87 | U13: =round(AVERAGE(J13,'Juri 2'!J13,'Juri 1'!J13),2) -> 85 | V13: =round(AVERAGE(K13,'Juri 2'!K13,'Juri 1'!K13),2) -> 88
C14: 5 | D14: Eka Saputra | E14: Laki-laki | F14: Teknik Sipil | G14: 2024 | H14: 85 | I14: 83 | J14: 83 | K14: 81 | L14: 84 | M14: 82 | N14: 83 | O14: 89 | P14: =(H14+I14+J14+K14+L14+M14+N14+O14)/8 -> 83.75 | R14: =round(AVERAGE(L14,'Juri 2'!L14),2) -> 86 | S14: =round(AVERAGE(H14,'Juri 2'!H14,'Juri 1'!H14),2) -> 83.67 | T14: =round(AVERAGE(I14,'Juri 2'!I14,'Juri 1'!I14),2) -> 86 | U14: =round(AVERAGE(J14,'Juri 2'!J14,'Juri 1'!J14),2) -> 86 | V14: =round(AVERAGE(K14,'Juri 2'!K14,'Juri 1'!K14),2) -> 83
C15: 6 | D15: Fajar Ramadhan | E15: Laki-laki | F15: Teknik Mesin | G15: 2023 | H15: 93 | I15: 94 | J15: 90 | K15: 90 | L15: 92 | M15: 89 | N15: 89 | O15: 90 | P15: =(H15+I15+J15+K15+L15+M15+N15+O15)/8 -> 90.875 | R15: =round(AVERAGE(L15,'Juri 2'!L15),2) -> 89.5 | S15: =round(AVERAGE(H15,'Juri 2'!H15,'Juri 1'!H15),2) -> 88.33 | T15: =round(AVERAGE(I15,'Juri 2'!I15,'Juri 1'!I15),2) -> 88.67 | U15: =round(AVERAGE(J15,'Juri 2'!J15,'Juri 1'!J15),2) -> 89 | V15: =round(AVERAGE(K15,'Juri 2'!K15,'Juri 1'!K15),2) -> 87.33
C16: 7 | D16: Gita Permata | E16: Perempuan | F16: Teknik Informatika dan Komputer | G16: 2024 | H16: 90 | I16: 90 | J16: 90 | K16: 90 | L16: 88 | M16: 90 | N16: 88 | O16: 90 | P16: =(H16+I16+J16+K16+L16+M16+N16+O16)/8 -> 89.5 | R16: =round(AVERAGE(L16,'Juri 2'!L16),2) -> 88 | S16: =round(AVERAGE(H16,'Juri 2'!H16,'Juri 1'!H16),2) -> 87.67 | T16: =round(AVERAGE(I16,'Juri 2'!I16,'Juri 1'!I16),2) -> 86.67 | U16: =round(AVERAGE(J16,'Juri 2'!J16,'Juri 1'!J16),2) -> 86.67 | V16: =round(AVERAGE(K16,'Juri 2'!K16,'Juri 1'!K16),2) -> 88.33
C17: 8 | D17: Hendra Wijaya | E17: Laki-laki | F17: Teknik Sipil | G17: 2024 | H17: 80 | I17: 80 | J17: 83 | K17: 80 | L17: 78 | M17: 70 | N17: 77 | O17: 90 | P17: =(H17+I17+J17+K17+L17+M17+N17+O17)/8 -> 79.75 | R17: =round(AVERAGE(L17,'Juri 2'!L17),2) -> 81.5 | S17: =round(AVERAGE(H17,'Juri 2'!H17,'Juri 1'!H17),2) -> 80.67 | T17: =round(AVERAGE(I17,'Juri 2'!I17,'Juri 1'!I17),2) -> 83.33 | U17: =round(AVERAGE(J17,'Juri 2'!J17,'Juri 1'!J17),2) -> 83.33 | V17: =round(AVERAGE(K17,'Juri 2'!K17,'Juri 1'!K17),2) -> 81.67
C18: 9 | D18: Indah Puspitasari | E18: Perempuan | F18: Teknik Mesin | G18: 2024 | H18: 95 | I18: 90 | J18: 90 | K18: 90 | L18: 90 | M18: 90 | N18: 90 | O18: 90 | P18: =(H18+I18+J18+K18+L18+M18+N18+O18)/8 -> 90.625 | R18: =round(AVERAGE(L18,'Juri 2'!L18),2) -> 87.5 | S18: =round(AVERAGE(H18,'Juri 2'!H18,'Juri 1'!H18),2) -> 92.67 | T18: =round(AVERAGE(I18,'Juri 2'!I18,'Juri 1'!I18),2) -> 85.67 | U18: =round(AVERAGE(J18,'Juri 2'!J18,'Juri 1'!J18),2) -> 87.33 | V18: =round(AVERAGE(K18,'Juri 2'!K18,'Juri 1'!K18),2) -> 84.33
C19: 10 | D19: Joko Hartono | E19: Laki-laki | F19: Administrasi Niaga | G19: 2024 | H19: 85 | I19: 85 | J19: 85 | K19: 89 | L19: 90 | M19: 80 | N19: 85 | O19: 90 | P19: =(H19+I19+J19+K19+L19+M19+N19+O19)/8 -> 86.125 | R19: =round(AVERAGE(L19,'Juri 2'!L19),2) -> 89 | S19: =round(AVERAGE(H19,'Juri 2'!H19,'Juri 1'!H19),2) -> 85 | T19: =round(AVERAGE(I19,'Juri 2'!I19,'Juri 1'!I19),2) -> 84 | U19: =round(AVERAGE(J19,'Juri 2'!J19,'Juri 1'!J19),2) -> 85 | V19: =round(AVERAGE(K19,'Juri 2'!K19,'Juri 1'!K19),2) -> 88.67
C20: 11 | D20: Kartika Sari | E20: Perempuan | F20: Akutansi | G20: 2023 | H20: 90 | I20: 90 | J20: 90 | K20: 90 | L20: 88 | M20: 88 | N20: 88 | O20: 90 | P20: =(H20+I20+J20+K20+L20+M20+N20+O20)/8 -> 89.25 | R20: =round(AVERAGE(L20,'Juri 2'!L20),2) -> 86.5 | S20: =round(AVERAGE(H20,'Juri 2'!H20,'Juri 1'!H20),2) -> 85 | T20: =round(AVERAGE(I20,'Juri 2'!I20,'Juri 1'!I20),2) -> 87.67 | U20: =round(AVERAGE(J20,'Juri 2'!J20,'Juri 1'!J20),2) -> 87.33 | V20: =round(AVERAGE(K20,'Juri 2'!K20,'Juri 1'!K20),2) -> 87.67
C21: 12 | D21: Laila Fitriani | E21: Perempuan | F21: Administrasi Niaga | G21: 2024 | H21: 90 | I21: 90 | J21: 90 | K21: 90 | L21: 90 | M21: 88 | N21: 90 | O21: 90 | P21: =(H21+I21+J21+K21+L21+M21+N21+O21)/8 -> 89.75 | R21: =round(AVERAGE(L21,'Juri 2'!L21),2) -> 87.5 | S21: =round(AVERAGE(H21,'Juri 2'!H21,'Juri 1'!H21),2) -> 86.67 | T21: =round(AVERAGE(I21,'Juri 2'!I21,'Juri 1'!I21),2) -> 85.33 | U21: =round(AVERAGE(J21,'Juri 2'!J21,'Juri 1'!J21),2) -> 86.67 | V21: =round(AVERAGE(K21,'Juri 2'!K21,'Juri 1'!K21),2) -> 86.67
... C58: 49 | D58: Teguh Prabowo | E58: Laki-laki | F58: Administrasi Niaga | G58: 2023 | H58: 90 | I58: 83 | J58: 84 | K58: 83 | L58: 82 | M58: 85 | N58: 89 | O58: 90 | P58: =(H58+I58+J58+K58+L58+M58+N58+O58)/8 -> 85.75 | R58: =round(AVERAGE(L58,'Juri 2'!L58),2) -> 81 | S58: =round(AVERAGE(H58,'Juri 2'!H58,'Juri 1'!H58),2) -> 86.67 | T58: =round(AVERAGE(I58,'Juri 2'!I58,'Juri 1'!I58),2) -> 84 | U58: =round(AVERAGE(J58,'Juri 2'!J58,'Juri 1'!J58),2) -> 84 | V58: =round(AVERAGE(K58,'Juri 2'!K58,'Juri 1'!K58),2) -> 83
C59: 50 | D59: Anisa Rahmawati | P59: #DIV/0!
C63: BOBOT | H63: 0.25 | I63: 0.2 | J63: 0.3 | K63: 0.25

Sheet Perhitungan ARAS
B2: No | C2: NAMA PESERTA | D2: JENIS KELAMIN | E2: JURUSAN | F2: ANGKATAN | G2: Ekspresi, Etika, Kepercayaan Diri | H2: Berpikir Kritis, Kreatif, Inisiatif, | I2: Komitmen Terhadap Duta dan Institusi | J2: Kemampuan Komunikasi, Argumentasi | K2: Personaliti Kepemimpinan & Keteraturan | L2: Manajemen Emosi | M2: Sikap Kooperatif | N2: Penilaian Diri dan Tujuan Pribadi | O2: Opening & Public Speaking | P2: Wawasan & Keilmuan | Q2: Kemampuan Berbahasa inggris | R2: Personaliti Kepemimpinan | S2: Body Language | T2: Kreativitas dan Invoasi | U2: Grooming & Look
B3: 0 | C3: A0 | D3: ANONIM | E3: ANONIM | F3: 2024 | G3: =MAX(G4:G52) -> 92.667 | H3: =MAX(H4:H52) -> 88.667 | I3: =MAX(I4:I52) -> 89 | J3: =MAX(J4:J52) -> 88.667 | K3: =MAX(K4:K52) -> 90 | L3: =MAX(L4:L52) -> 82 | M3: =MAX(M4:M52) -> 90 | N3: =MAX(N4:N52) -> 90 | ... U3: =MAX(U4:U52) -> 90
B4: 1 | C4: Aditya Pratama | D4: Laki-laki | E4: Administrasi Niaga | F4: 2024 | G4: =round(AVERAGE('Juri 3'!H10,'Juri 2'!H10,'Juri 1'!H10),3) -> 85 | H4: =round(AVERAGE('Juri 3'!I10,'Juri 2'!I10,'Juri 1'!I10),3) -> 88.333 | I4: =round(AVERAGE('Juri 3'!J10,'Juri 2'!J10,'Juri 1'!J10),3) -> 85 | J4: =round(AVERAGE('Juri 3'!K10,'Juri 2'!K10,'Juri 1'!K10),3) -> 84.333 | K4: 80 | L4: 74 | M4: 80 | N4: 90 | O4: =round(AVERAGE(I4,'Juri 2'!I3),3) -> 85 | P4: 85 | Q4: 70 | R4: 85 | S4: 88 | T4: 88 | U4: 90
B5: 2 | C5: Budi Santoso | D5: Laki-laki | E5: Teknik Grafika dan Penerbitan | F5: 2024 | G5: =round(AVERAGE('Juri 3'!H11,'Juri 2'!H11,'Juri 1'!H11),3) -> 77.667 | H5: =round(AVERAGE('Juri 3'!I11,'Juri 2'!I11,'Juri 1'!I11),3) -> 80 | I5: =round(AVERAGE('Juri 3'!J11,'Juri 2'!J11,'Juri 1'!J11),3) -> 79 | J5: =round(AVERAGE('Juri 3'!K11,'Juri 2'!K11,'Juri 1'!K11),3) -> 82.333 | K5: 80 | L5: 82 | M5: 80 | N5: 80 | O5: =round(AVERAGE(I5,'Juri 2'!I4),3) -> 79 | P5: 85 | Q5: 70 | R5: 85 | S5: 80 | T5: 80 | U5: 80
B6: 3 | C6: Citra Lestari | D6: Perempuan | E6: Teknik Sipil | F6: 2023 | G6: =round(AVERAGE('Juri 3'!H12,'Juri 2'!H12,'Juri 1'!H12),3) -> 88.333 | H6: =round(AVERAGE('Juri 3'!I12,'Juri 2'!I12,'Juri 1'!I12),3) -> 86 | I6: =round(AVERAGE('Juri 3'!J12,'Juri 2'!J12,'Juri 1'!J12),3) -> 87.667 | J6: =round(AVERAGE('Juri 3'!K12,'Juri 2'!K12,'Juri 1'!K12),3) -> 87.667 | K6: 85 | L6: 80 | M6: 85 | N6: 80 | O6: =round(AVERAGE(I6,'Juri 2'!I5),3) -> 87.667 | P6: 90 | Q6: 90 | R6: 90 | S6: 90 | T6: 85 | U6: 89
B7: 4 | C7: Dwi Anggraini | D7: Perempuan | E7: Akutansi | F7: 2024 | G7: =round(AVERAGE('Juri 3'!H13,'Juri 2'!H13,'Juri 1'!H13),3) -> 86 | H7: =round(AVERAGE('Juri 3'!I13,'Juri 2'!I13,'Juri 1'!I13),3) -> 87 | I7: =round(AVERAGE('Juri 3'!J13,'Juri 2'!J13,'Juri 1'!J13),3) -> 85 | J7: =round(AVERAGE('Juri 3'!K13,'Juri 2'!K13,'Juri 1'!K13),3) -> 88 | K7: 75 | L7: 77 | M7: 86 | N7: 80 | O7: =round(AVERAGE(I7,'Juri 2'!I6),3) -> 85 | P7: 88 | Q7: 70 | R7: 85 | S7: 88 | T7: 85 | U7: 85
B8: 5 | C8: Eka Saputra | D8: Laki-laki | E8: Teknik Sipil | F8: 2024 | G8: =round(AVERAGE('Juri 3'!H14,'Juri 2'!H14,'Juri 1'!H14),3) -> 83.667 | H8: =round(AVERAGE('Juri 3'!I14,'Juri 2'!I14,'Juri 1'!I14),3) -> 86 | I8: =round(AVERAGE('Juri 3'!J14,'Juri 2'!J14,'Juri 1'!J14),3) -> 86 | J8: =round(AVERAGE('Juri 3'!K14,'Juri 2'!K14,'Juri 1'!K14),3) -> 83 | K8: 78 | L8: 70 | M8: 80 | N8: 80 | O8: =round(AVERAGE(I8,'Juri 2'!I7),3) -> 86 | P8: 88 | Q8: 70 | R8: 88 | S8: 82 | T8: 83 | U8: 89
B9: 6 | C9: Fajar Ramadhan | D9: Laki-laki | E9: Teknik Mesin | F9: 2023 | G9: =round(AVERAGE('Juri 3'!H15,'Juri 2'!H15,'Juri 1'!H15),3) -> 88.333 | H9: =round(AVERAGE('Juri 3'!I15,'Juri 2'!I15,'Juri 1'!I15),3) -> 88.667 | I9: =round(AVERAGE('Juri 3'!J15,'Juri 2'!J15,'Juri 1'!J15),3) -> 89 | J9: =round(AVERAGE('Juri 3'!K15,'Juri 2'!K15,'Juri 1'!K15),3) -> 87.333 | K9: 85 | L9: 80 | M9: 85 | N9: 80 | O9: =round(AVERAGE(I9,'Juri 2'!I8),3) -> 89 | P9: 87 | Q9: 70 | R9: 87 | S9: 89 | T9: 89 | U9: 90
B10: 7 | C10: Gita Permata | D10: Perempuan | E10: Teknik Informatika dan Komputer | F10: 2024 | G10: =round(AVERAGE('Juri 3'!H16,'Juri 2'!H16,'Juri 1'!H16),3) -> 87.667 | H10: =round(AVERAGE('Juri 3'!I16,'Juri 2'!I16,'Juri 1'!I16),3) -> 86.667 | I10: =round(AVERAGE('Juri 3'!J16,'Juri 2'!J16,'Juri 1'!J16),3) -> 86.667 | J10: =round(AVERAGE('Juri 3'!K16,'Juri 2'!K16,'Juri 1'!K16),3) -> 88.333 | K10: 75 | L10: 77 | M10: 80 | N10: 80 | O10: =round(AVERAGE(I10,'Juri 2'!I9),3) -> 86.667 | P10: 88 | Q10: 80 | R10: 88 | S10: 90 | T10: 88 | U10: 90
B11: 8 | C11: Hendra Wijaya | D11: Laki-laki | E11: Teknik Sipil | F11: 2024 | G11: =round(AVERAGE('Juri 3'!H17,'Juri 2'!H17,'Juri 1'!H17),3) -> 80.667 | H11: =round(AVERAGE('Juri 3'!I17,'Juri 2'!I17,'Juri 1'!I17),3) -> 83.333 | I11: =round(AVERAGE('Juri 3'!J17,'Juri 2'!J17,'Juri 1'!J17),3) -> 83.333 | J11: =round(AVERAGE('Juri 3'!K17,'Juri 2'!K17,'Juri 1'!K17),3) -> 81.667 | K11: 80 | L11: 70 | M11: 87 | N11: 85 | O11: =round(AVERAGE(I11,'Juri 2'!I10),3) -> 84.167 | P11: 85 | Q11: 70 | R11: 85 | S11: 70 | T11: 77 | U11: 90
B12: 9 | C12: Indah Puspitasari | D12: Perempuan | E12: Teknik Mesin | F12: 2024 | G12: =round(AVERAGE('Juri 3'!H18,'Juri 2'!H18,'Juri 1'!H18),3) -> 92.667 | H12: =round(AVERAGE('Juri 3'!I18,'Juri 2'!I18,'Juri 1'!I18),3) -> 85.667 | I12: =round(AVERAGE('Juri 3'!J18,'Juri 2'!J18,'Juri 1'!J18),3) -> 87.333 | J12: =round(AVERAGE('Juri 3'!K18,'Juri 2'!K18,'Juri 1'!K18),3) -> 84.333 | K12: 70 | L12: 75 | M12: 87 | N12: 85 | O12: =round(AVERAGE(I12,'Juri 2'!I11),3) -> 85.167 | P12: 88 | Q12: 70 | R12: 85 | S12: 90 | T12: 90 | U12: 90
B13: 10 | C13: Joko Hartono | D13: Laki-laki | E13: Administrasi Niaga | F13: 2024 | G13: =round(AVERAGE('Juri 3'!H19,'Juri 2'!H19,'Juri 1'!H19),3) -> 85 | H13: =round(AVERAGE('Juri 3'!I19,'Juri 2'!I19,'Juri 1'!I19),3) -> 84 | I13: =round(AVERAGE('Juri 3'!J19,'Juri 2'!J19,'Juri 1'!J19),3) -> 85 | J13: =round(AVERAGE('Juri 3'!K19,'Juri 2'!K19,'Juri 1'!K19),3) -> 88.667 | K13: 80 | L13: 76 | M13: 80 | N13: 80 | O13: =round(AVERAGE(I13,'Juri 2'!I12),3) -> 86.5 | P13: 85 | Q13: 70 | R13: 85 | S13: 80 | T13: 85 | U13: 90
B14: 11 | C14: Kartika Sari | D14: Perempuan | E14: Akutansi | F14: 2023 | G14: =round(AVERAGE('Juri 3'!H20,'Juri 2'!H20,'Juri 1'!H20),3) -> 85 | H14: =round(AVERAGE('Juri 3'!I20,'Juri 2'!I20,'Juri 1'!I20),3) -> 87.667 | I14: =round(AVERAGE('Juri 3'!J20,'Juri 2'!J20,'Juri 1'!J20),3) -> 87.333 | J14: =round(AVERAGE('Juri 3'!K20,'Juri 2'!K20,'Juri 1'!K20),3) -> 87.667 | K14: 85 | L14: 70 | M14: 85 | N14: 80 | O14: =round(AVERAGE(I14,'Juri 2'!I13),3) -> 87.667 | P14: 85 | Q14: 70 | R14: 88 | S14: 88 | T14: 88 | U14: 90
B15: 12 | C15: Laila Fitriani | D15: Perempuan | E15: Administrasi Niaga | F15: 2024 | G15: =round(AVERAGE('Juri 3'!H21,'Juri 2'!H21,'Juri 1'!H21),3) -> 86.667 | H15: =round(AVERAGE('Juri 3'!I21,'Juri 2'!I21,'Juri 1'!I21),3) -> 85.333 | I15: =round(AVERAGE('Juri 3'!J21,'Juri 2'!J21,'Juri 1'!J21),3) -> 86.667 | J15: =round(AVERAGE('Juri 3'!K21,'Juri 2'!K21,'Juri 1'!K21),3) -> 86.667 | K15: 80 | L15: 76 | M15: 90 | N15: 83 | O15: =round(AVERAGE(I15,'Juri 2'!I14),3) -> 87.334 | P15: 85 | Q15: 90 | R15: 88 | S15: 88 | T15: 90 | U15: 90
... B52: 49 | C52: Teguh Prabowo | D52: Laki-laki | E52: Administrasi Niaga | F52: 2023 | G52: =round(AVERAGE('Juri 3'!H58,'Juri 2'!H58,'Juri 1'!H58),3) -> 86.667 | H52: =round(AVERAGE('Juri 3'!I58,'Juri 2'!I58,'Juri 1'!I58),3) -> 84 | I52: =round(AVERAGE('Juri 3'!J58,'Juri 2'!J58,'Juri 1'!J58),3) -> 84 | J52: =round(AVERAGE('Juri 3'!K58,'Juri 2'!K58,'Juri 1'!K58),3) -> 83 | K52: 85 | L52: 78 | M52: 75 | N52: 90 | O52: =round(AVERAGE(I52,'Juri 2'!I51),3) -> 84.5 | P52: 86 | Q52: 70 | R52: 86 | S52: 85 | T52: 89 | U52: 90
B53: TOTAL | G53: =sum(G4:G52) -> 4168.335 | H53: =sum(H4:H52) -> 4144.335 | I53: =sum(I4:I52) -> 4177.001 | J53: =sum(J4:J52) -> 4152.003 | K53: =sum(K4:K52) -> 3963 | L53: =sum(L4:L52) -> 3699 | M53: =sum(M4:M52) -> 4103 | N53: =sum(N4:N52) -> 4049 | ... U53: =sum(U4:U52) -> 4364
B55: Kriteria | C55: C1 | D55: C2 | E55: C3 | F55: C4 | G55: C5 | H55: C6 | I55: C7 | J55: C8 | K55: C9 | L55: C10 | M55: C11 | N55: C12 | O55: C13 | P55: C14 | Q55: C15 | R55: C16
B56: Bobot (%) | C56: 8 | D56: 8 | E56: 7 | F56: 8 | G56: 7 | H56: 5 | I56: 5 | J56: 5 | K56: 8 | L56: 10 | M56: 8 | N56: 5 | O56: 5 | P56: 4 | Q56: 4 | R56: 3
B57: Bobot (Desimal) | C57: 0.08 | D57: 0.08 | E57: 0.07 | F57: 0.08 | G57: 0.07 | H57: 0.05 | I57: 0.05 | J57: 0.05 | K57: 0.08 | L57: 0.1 | M57: 0.08 | N57: 0.05 | O57: 0.05 | P57: 0.04 | Q57: 0.04 | R57: 0.03
B59: No | C59: NAMA PESERTA | D59: JENIS KELAMIN | E59: JURUSAN | F59: ANGKATAN | G59: Ekspresi, Etika, Kepercayaan Diri | H59: Berpikir Kritis, Kreatif, Inisiatif, | I59: Komitmen Terhadap Duta dan Institusi | J59: Kemampuan Komunikasi, Argumentasi | K59: Personaliti Kepemimpinan & Keteraturan | L59: Manajemen Emosi | M59: Sikap Kooperatif | N59: Penilaian Diri dan Tujuan Pribadi | O59: Opening & Public Speaking | P59: Wawasan & Keilmuan | Q59: Kemampuan Berbahasa inggris | R59: Personaliti Kepemimpinan | S59: Opening & Public Speaking | T59: Body Language | U59: Kreativitas dan Invoasi
C60: A0 | D60: ANONIM | E60: ANONIM | F60: 2024 | G60: =round(G3/$G$53,3) -> 0.022 | H60: =round(H3/$H$53,3) -> 0.021 | I60: =round(I3/$I$53,3) -> 0.021 | J60: =round(J3/$J$53,3) -> 0.021 | K60: =round(K3/$K$53,3) -> 0.023 | L60: =round(L3/$L$53,3) -> 0.022 | M60: =round(M3/$M$53,3) -> 0.022 | N60: =round(N3/$N$53,3) -> 0.022 | O60: =round(O3/$O$53,3) -> 0.021 | P60: =round(P3/$P$53,3) -> 0.021 | Q60: =round(Q3/$Q$53,3) -> 0.025 | R60: =round(R3/$R$53,3) -> 0.021 | S60: =round(S3/$S$53,3) -> 0.022 | T60: =round(T3/$T$53,3) -> 0.022 | U60: =round(U3/$U$53,3) -> 0.021
B61: 1 | C61: Aditya Pratama | D61: Laki-laki | E61: Administrasi Niaga | F61: 2024 | G61: =round(G4/$G$53,3) -> 0.02 | H61: =round(H4/$H$53,3) -> 0.021 | I61: =round(I4/$I$53,3) -> 0.02 | J61: =round(J4/$J$53,3) -> 0.02 | K61: =round(K4/$K$53,3) -> 0.02 | L61: =round(L4/$L$53,3) -> 0.02 | M61: =round(M4/$M$53,3) -> 0.019 | N61: =round(N4/$N$53,3) -> 0.022 | O61: =round(O4/$O$53,3) -> 0.02 | P61: =round(P4/$P$53,3) -> 0.02 | Q61: =round(Q4/$Q$53,3) -> 0.019 | R61: =round(R4/$R$53,3) -> 0.02 | S61: =round(S4/$S$53,3) -> 0.021 | T61: =round(T4/$T$53,3) -> 0.021 | U61: =round(U4/$U$53,3) -> 0.021
B62: 2 | C62: Budi Santoso | D62: Laki-laki | E62: Teknik Grafika dan Penerbitan | F62: 2024 | G62: =round(G5/$G$53,3) -> 0.019 | H62: =round(H5/$H$53,3) -> 0.019 | I62: =round(I5/$I$53,3) -> 0.019 | J62: =round(J5/$J$53,3) -> 0.02 | K62: =round(K5/$K$53,3) -> 0.02 | L62: =round(L5/$L$53,3) -> 0.022 | M62: =round(M5/$M$53,3) -> 0.019 | N62: =round(N5/$N$53,3) -> 0.02 | O62: =round(O5/$O$53,3) -> 0.019 | P62: =round(P5/$P$53,3) -> 0.02 | Q62: =round(Q5/$Q$53,3) -> 0.019 | R62: =round(R5/$R$53,3) -> 0.02 | S62: =round(S5/$S$53,3) -> 0.019 | T62: =round(T5/$T$53,3) -> 0.019 | U62: =round(U5/$U$53,3) -> 0.018
B63: 3 | C63: Citra Lestari | D63: Perempuan | E63: Teknik Sipil | F63: 2023 | G63: =round(G6/$G$53,3) -> 0.021 | H63: =round(H6/$H$53,3) -> 0.021 | I63: =round(I6/$I$53,3) -> 0.021 | J63: =round(J6/$J$53,3) -> 0.021 | K63: =round(K6/$K$53,3) -> 0.021 | L63: =round(L6/$L$53,3) -> 0.022 | M63: =round(M6/$M$53,3) -> 0.021 | N63: =round(N6/$N$53,3) -> 0.02 | O63: =round(O6/$O$53,3) -> 0.021 | P63: =round(P6/$P$53,3) -> 0.021 | Q63: =round(Q6/$Q$53,3) -> 0.025 | R63: =round(R6/$R$53,3) -> 0.021 | S63: =round(S6/$S$53,3) -> 0.022 | T63: =round(T6/$T$53,3) -> 0.02 | U63: =round(U6/$U$53,3) -> 0.02
B64: 4 | C64: Dwi Anggraini | D64: Perempuan | E64: Akutansi | F64: 2024 | G64: =round(G7/$G$53,3) -> 0.021 | H64: =round(H7/$H$53,3) -> 0.021 | I64: =round(I7/$I$53,3) -> 0.02 | J64: =round(J7/$J$53,3) -> 0.021 | K64: =round(K7/$K$53,3) -> 0.019 | L64: =round(L7/$L$53,3) -> 0.021 | M64: =round(M7/$M$53,3) -> 0.021 | N64: =round(N7/$N$53,3) -> 0.02 | O64: =round(O7/$O$53,3) -> 0.02 | P64: =round(P7/$P$53,3) -> 0.021 | Q64: =round(Q7/$Q$53,3) -> 0.019 | R64: =round(R7/$R$53,3) -> 0.02 | S64: =round(S7/$S$53,3) -> 0.021 | T64: =round(T7/$T$53,3) -> 0.02 | U64: =round(U7/$U$53,3) -> 0.019
B65: 5 | C65: Eka Saputra | D65: Laki-laki | E65: Teknik Sipil | F65: 2024 | G65: =round(G8/$G$53,3) -> 0.02 | H65: =round(H8/$H$53,3) -> 0.021 | I65: =round(I8/$I$53,3) -> 0.021 | J65: =round(J8/$J$53,3) -> 0.02 | K65: =round(K8/$K$53,3) -> 0.02 | L65: =round(L8/$L$53,3) -> 0.019 | M65: =round(M8/$M$53,3) -> 0.019 | N65: =round(N8/$N$53,3) -> 0.02 | O65: =round(O8/$O$53,3) -> 0.02 | P65: =round(P8/$P$53,3) -> 0.021 | Q65: =round(Q8/$Q$53,3) -> 0.019 | R65: =round(R8/$R$53,3) -> 0.021 | S65: =round(S8/$S$53,3) -> 0.02 | T65: =round(T8/$T$53,3) -> 0.02 | U65: =round(U8/$U$53,3) -> 0.02
B66: 6 | C66: Fajar Ramadhan | D66: Laki-laki | E66: Teknik Mesin | F66: 2023 | G66: =round(G9/$G$53,3) -> 0.021 | H66: =round(H9/$H$53,3) -> 0.021 | I66: =round(I9/$I$53,3) -> 0.021 | J66: =round(J9/$J$53,3) -> 0.021 | K66: =round(K9/$K$53,3) -> 0.021 | L66: =round(L9/$L$53,3) -> 0.022 | M66: =round(M9/$M$53,3) -> 0.021 | N66: =round(N9/$N$53,3) -> 0.02 | O66: =round(O9/$O$53,3) -> 0.021 | P66: =round(P9/$P$53,3) -> 0.021 | Q66: =round(Q9/$Q$53,3) -> 0.019 | R66: =round(R9/$R$53,3) -> 0.021 | S66: =round(S9/$S$53,3) -> 0.021 | T66: =round(T9/$T$53,3) -> 0.021 | U66: =round(U9/$U$53,3) -> 0.021
B67: 7 | C67: Gita Permata | D67: Perempuan | E67: Teknik Informatika dan Komputer | F67: 2024 | G67: =round(G10/$G$53,3) -> 0.021 | H67: =round(H10/$H$53,3) -> 0.021 | I67: =round(I10/$I$53,3) -> 0.021 | J67: =round(J10/$J$53,3) -> 0.021 | K67: =round(K10/$K$53,3) -> 0.019 | L67: =round(L10/$L$53,3) -> 0.021 | M67: =round(M10/$M$53,3) -> 0.019 | N67: =round(N10/$N$53,3) -> 0.02 | O67: =round(O10/$O$53,3) -> 0.021 | P67: =round(P10/$P$53,3) -> 0.021 | Q67: =round(Q10/$Q$53,3) -> 0.022 | R67: =round(R10/$R$53,3) -> 0.021 | S67: =round(S10/$S$53,3) -> 0.022 | T67: =round(T10/$T$53,3) -> 0.021 | U67: =round(U10/$U$53,3) -> 0.021
B68: 8 | C68: Hendra Wijaya | D68: Laki-laki | E68: Teknik Sipil | F68: 2024 | G68: =round(G11/$G$53,3) -> 0.019 | H68: =round(H11/$H$53,3) -> 0.02 | I68: =round(I11/$I$53,3) -> 0.02 | J68: =round(J11/$J$53,3) -> 0.02 | K68: =round(K11/$K$53,3) -> 0.02 | L68: =round(L11/$L$53,3) -> 0.019 | M68: =round(M11/$M$53,3) -> 0.021 | N68: =round(N11/$N$53,3) -> 0.021 | O68: =round(O11/$O$53,3) -> 0.02 | P68: =round(P11/$P$53,3) -> 0.02 | Q68: =round(Q11/$Q$53,3) -> 0.019 | R68: =round(R11/$R$53,3) -> 0.02 | S68: =round(S11/$S$53,3) -> 0.017 | T68: =round(T11/$T$53,3) -> 0.018 | U68: =round(U11/$U$53,3) -> 0.021
B69: 9 | C69: Indah Puspitasari | D69: Perempuan | E69: Teknik Mesin | F69: 2024 | G69: =round(G12/$G$53,3) -> 0.022 | H69: =round(H12/$H$53,3) -> 0.021 | I69: =round(I12/$I$53,3) -> 0.021 | J69: =round(J12/$J$53,3) -> 0.02 | K69: =round(K12/$K$53,3) -> 0.018 | L69: =round(L12/$L$53,3) -> 0.02 | M69: =round(M12/$M$53,3) -> 0.021 | N69: =round(N12/$N$53,3) -> 0.021 | O69: =round(O12/$O$53,3) -> 0.02 | P69: =round(P12/$P$53,3) -> 0.021 | Q69: =round(Q12/$Q$53,3) -> 0.019 | R69: =round(R12/$R$53,3) -> 0.02 | S69: =round(S12/$S$53,3) -> 0.022 | T69: =round(T12/$T$53,3) -> 0.022 | U69: =round(U12/$U$53,3) -> 0.021
B70: 10 | C70: Joko Hartono | D70: Laki-laki | E70: Administrasi Niaga | F70: 2024 | G70: =round(G13/$G$53,3) -> 0.02 | H70: =round(H13/$H$53,3) -> 0.02 | I70: =round(I13/$I$53,3) -> 0.02 | J70: =round(J13/$J$53,3) -> 0.021 | K70: =round(K13/$K$53,3) -> 0.02 | L70: =round(L13/$L$53,3) -> 0.021 | M70: =round(M13/$M$53,3) -> 0.019 | N70: =round(N13/$N$53,3) -> 0.02 | O70: =round(O13/$O$53,3) -> 0.021 | P70: =round(P13/$P$53,3) -> 0.02 | Q70: =round(Q13/$Q$53,3) -> 0.019 | R70: =round(R13/$R$53,3) -> 0.02 | S70: =round(S13/$S$53,3) -> 0.019 | T70: =round(T13/$T$53,3) -> 0.02 | U70: =round(U13/$U$53,3) -> 0.021
B71: 11 | C71: Kartika Sari | D71: Perempuan | E71: Akutansi | F71: 2023 | G71: =round(G14/$G$53,3) -> 0.02 | H71: =round(H14/$H$53,3) -> 0.021 | I71: =round(I14/$I$53,3) -> 0.021 | J71: =round(J14/$J$53,3) -> 0.021 | K71: =round(K14/$K$53,3) -> 0.021 | L71: =round(L14/$L$53,3) -> 0.019 | M71: =round(M14/$M$53,3) -> 0.021 | N71: =round(N14/$N$53,3) -> 0.02 | O71: =round(O14/$O$53,3) -> 0.021 | P71: =round(P14/$P$53,3) -> 0.02 | Q71: =round(Q14/$Q$53,3) -> 0.019 | R71: =round(R14/$R$53,3) -> 0.021 | S71: =round(S14/$S$53,3) -> 0.021 | T71: =round(T14/$T$53,3) -> 0.021 | U71: =round(U14/$U$53,3) -> 0.021
B72: 12 | C72: Laila Fitriani | D72: Perempuan | E72: Administrasi Niaga | F72: 2024 | G72: =round(G15/$G$53,3) -> 0.021 | H72: =round(H15/$H$53,3) -> 0.021 | I72: =round(I15/$I$53,3) -> 0.021 | J72: =round(J15/$J$53,3) -> 0.021 | K72: =round(K15/$K$53,3) -> 0.02 | L72: =round(L15/$L$53,3) -> 0.021 | M72: =round(M15/$M$53,3) -> 0.022 | N72: =round(N15/$N$53,3) -> 0.02 | O72: =round(O15/$O$53,3) -> 0.021 | P72: =round(P15/$P$53,3) -> 0.02 | Q72: =round(Q15/$Q$53,3) -> 0.025 | R72: =round(R15/$R$53,3) -> 0.021 | S72: =round(S15/$S$53,3) -> 0.021 | T72: =round(T15/$T$53,3) -> 0.022 | U72: =round(U15/$U$53,3) -> 0.021
... B109: 49 | C109: Teguh Prabowo | D109: Laki-laki | E109: Administrasi Niaga | F109: 2023 | G109: =round(G52/$G$53,3) -> 0.021 | H109: =round(H52/$H$53,3) -> 0.02 | I109: =round(I52/$I$53,3) -> 0.02 | J109: =round(J52/$J$53,3) -> 0.02 | K109: =round(K52/$K$53,3) -> 0.021 | L109: =round(L52/$L$53,3) -> 0.021 | M109: =round(M52/$M$53,3) -> 0.018 | N109: =round(N52/$N$53,3) -> 0.022 | O109: =round(O52/$O$53,3) -> 0.02 | P109: =round(P52/$P$53,3) -> 0.02 | Q109: =round(Q52/$Q$53,3) -> 0.019 | R109: =round(R52/$R$53,3) -> 0.02 | S109: =round(S52/$S$53,3) -> 0.02 | T109: =round(T52/$T$53,3) -> 0.021 | U109: =round(U52/$U$53,3) -> 0.021
B112: No | C112: NAMA PESERTA | D112: JENIS KELAMIN | E112: JURUSAN | F112: ANGKATAN | G112: Ekspresi, Etika, Kepercayaan Diri | H112: Berpikir Kritis, Kreatif, Inisiatif, | I112: Komitmen Terhadap Duta dan Institusi | J112: Kemampuan Komunikasi, Argumentasi | K112: Personaliti Kepemimpinan & Keteraturan | L112: Manajemen Emosi | M112: Sikap Kooperatif | N112: Penilaian Diri dan Tujuan Pribadi | O112: Opening & Public Speaking | P112: Wawasan & Keilmuan | Q112: Kemampuan Berbahasa inggris | R112: Personaliti Kepemimpinan | S112: Opening & Public Speaking | T112: Body Language | U112: Kreativitas dan Invoasi | V112: Si | W112: Ki | Y112: Alternatif | Z112: Total Nilai Terbobot (Si​) | AA112: Tingkat Utilitas (Ki​) | AB112: Ranking Akhir
C113: A0 | D113: ANONIM | E113: ANONIM | F113: 2024 | G113: =G60*$C$57 -> 0.00176 | H113: =H60*$D$57 -> 0.00168 | I113: =I60*$E$57 -> 0.00147 | J113: =J60*$F$57 -> 0.00168 | K113: =K60*$G$57 -> 0.00161 | L113: =L60*$H$57 -> 0.0011 | M113: =M60*$I$57 -> 0.0011 | N113: =N60*$J$57 -> 0.0011 | O113: =O60*$K$57 -> 0.00168 | P113: =P60*$L$57 -> 0.0021 | Q113: =Q60*$M$57 -> 0.002 | R113: =R60*$N$57 -> 0.00105 | S113: =S60*$O$57 -> 0.0011 | T113: =T60*$P$57 -> 0.00088 | U113: =U60*$Q$57 -> 0.00084 | V113: =SUM(G113:U113) -> 0.02115 | Y113: A0 (Optimum Target) | Z113: 0.02324 | AA113: 1 | AB113: -
B114: 1 | C114: Aditya Pratama | D114: Laki-laki | E114: Administrasi Niaga | F114: 2024 | G114: =G61*$C$57 -> 0.0016 | H114: =H61*$D$57 -> 0.00168 | I114: =I61*$E$57 -> 0.0014 | J114: =J61*$F$57 -> 0.0016 | K114: =K61*$G$57 -> 0.0014 | L114: =L61*$H$57 -> 0.001 | M114: =M61*$I$57 -> 0.00095 | N114: =N61*$J$57 -> 0.0011 | O114: =O61*$K$57 -> 0.0016 | P114: =P61*$L$57 -> 0.002 | Q114: =Q61*$M$57 -> 0.00152 | R114: =R61*$N$57 -> 0.001 | S114: =S61*$O$57 -> 0.00105 | T114: =T61*$P$57 -> 0.00084 | U114: =U61*$Q$57 -> 0.00084 | V114: =SUM(G114:U114) -> 0.01958 | W114: =V114/$V$113 -> 0.92576832 | Y114: A3 | Z114: 0.02271 | AA114: 0.9772 | AB114: 1
B115: 2 | C115: Budi Santoso | D115: Laki-laki | E115: Teknik Grafika dan Penerbitan | F115: 2024 | G115: =G62*$C$57 -> 0.00152 | H115: =H62*$D$57 -> 0.00152 | I115: =I62*$E$57 -> 0.00133 | J115: =J62*$F$57 -> 0.0016 | K115: =K62*$G$57 -> 0.0014 | L115: =L62*$H$57 -> 0.0011 | M115: =M62*$I$57 -> 0.00095 | N115: =N62*$J$57 -> 0.001 | O115: =O62*$K$57 -> 0.00152 | P115: =P62*$L$57 -> 0.002 | Q115: =Q62*$M$57 -> 0.00152 | R115: =R62*$N$57 -> 0.001 | S115: =S62*$O$57 -> 0.00095 | T115: =T62*$P$57 -> 0.00076 | U115: =U62*$Q$57 -> 0.00072 | V115: =SUM(G115:U115) -> 0.01889 | W115: =V115/$V$113 -> 0.89314421 | Y115: A26 | Z115: 0.02251 | AA115: 0.9686 | AB115: 2
B116: 3 | C116: Citra Lestari | D116: Perempuan | E116: Teknik Sipil | F116: 2023 | G116: =G63*$C$57 -> 0.00168 | H116: =H63*$D$57 -> 0.00168 | I116: =I63*$E$57 -> 0.00147 | J116: =J63*$F$57 -> 0.00168 | K116: =K63*$G$57 -> 0.00147 | L116: =L63*$H$57 -> 0.0011 | M116: =M63*$I$57 -> 0.00105 | N116: =N63*$J$57 -> 0.001 | O116: =O63*$K$57 -> 0.00168 | P116: =P63*$L$57 -> 0.0021 | Q116: =Q63*$M$57 -> 0.002 | R116: =R63*$N$57 -> 0.00105 | S116: =S63*$O$57 -> 0.0011 | T116: =T63*$P$57 -> 0.0008 | U116: =U63*$Q$57 -> 0.0008 | V116: =SUM(G116:U116) -> 0.02066 | W116: =V116/$V$113 -> 0.97683215 | Y116: A11 | Z116: 0.02237 | AA116: 0.9626 | AB116: 3
B117: 4 | C117: Dwi Anggraini | D117: Perempuan | E117: Akutansi | F117: 2024 | G117: =G64*$C$57 -> 0.00168 | H117: =H64*$D$57 -> 0.00168 | I117: =I64*$E$57 -> 0.0014 | J117: =J64*$F$57 -> 0.00168 | K117: =K64*$G$57 -> 0.00133 | L117: =L64*$H$57 -> 0.00105 | M117: =M64*$I$57 -> 0.00105 | N117: =N64*$J$57 -> 0.001 | O117: =O64*$K$57 -> 0.0016 | P117: =P64*$L$57 -> 0.0021 | Q117: =Q64*$M$57 -> 0.00152 | R117: =R64*$N$57 -> 0.001 | S117: =S64*$O$57 -> 0.00105 | T117: =T64*$P$57 -> 0.0008 | U117: =U64*$Q$57 -> 0.00076 | V117: =SUM(G117:U117) -> 0.0197 | W117: =V117/$V$113 -> 0.93144208 | Y117: A10 | Z117: 0.02219 | AA117: 0.9548 | AB117: 4
...
